Workbook

Sheet NJIT Jersey Patch Valuation
A1: Gender | B1: Sport | C1: NJIT Ranking | D1: Home or Away | E1: Conference/Non Conference | F1: Opponent | G1: Opponent Rank | H1: Conf | I1: Date | J1: Day | K1: Time | L1: Network | M1: Distribution | N1: Exp % | O1: Imp/Spec | P1: Total Game Length (sec) | Q1: Screen Time % | R1: Raw Duration (sec) | S1: Visibility Weighting Factor (based on network) | T1: Adjusted Duration (sec) | U1: 30 sec Equivalents | V1: 30 sec Equivalents with Wearout Factor Adjustment | W1: Streaming/Broadcast CPM | X1: Onsite CPM | Y1: Total Attendance | Z1: Avg Viewers | AA1: Onsite Impressions | AB1: Onsite Value | AC1: Streaming/Broadcast Impressions | AD1: Streaming/Broadcast Value | AE1: Total Value | AF1: Total Impressions | AG1: CPM
A2: Mens | B2: Basketball | D2: Home | E2: Non-Conference | F2: Penn | H2: Ivy | I2: 11/4/2024 | J2: Mon | K2: 7:00 PM | L2: ESPN+ | M2: Streaming | N2: =KEY!$C$2 -> 0.65 | O2: =KEY!$D$2 -> 10 | P2: =KEY!$B$2 -> 7200 | Q2: =KEY!$E$2 -> 0.06 | R2: =P2*Q2 -> 432 | S2: =IFERROR(VLOOKUP($L2,KEY!$A$13:$G$84,4,FALSE),0.4) -> 0.4 | T2: =R2*S2 -> 172.8 | U2: =T2/30 -> 5.76 | V2: =U2*0.625 -> 3.6 | W2: =IFERROR(VLOOKUP($L2,KEY!$A$13:$G$84,7,FALSE),18) -> 18 | X2: 10 | Y2: 590 | Z2: 1500 | AA2: =Y2*O2*N2 -> 3835 | AB2: =(AA2/1000)*X2 -> 38.35 | AC2: =Z2*V2 -> 5400 | AD2: =(AC2/1000)*W2 -> 97.2 | AE2: =SUM(AB2,AD2) -> 135.55 | AF2: =AC2+AA2 -> 9235 | AG2: =IF(AF2=0,0,AE2/AF2*1000) -> 14.677856
A3: Mens | B3: Basketball | D3: Away | E3: Non-Conference | F3: Villanova | G3: 8 | H3: Big East | I3: 11/8/2024 | J3: Fri | K3: 8:30 PM | L3: FS1 | M3: National Linear | N3: =KEY!$C$2 -> 0.65 | O3: =KEY!$D$2 -> 10 | P3: =KEY!$B$2 -> 7200 | Q3: =KEY!$E$2 -> 0.06 | R3: =P3*Q3 -> 432 | S3: =IFERROR(VLOOKUP($L3,KEY!$A$13:$G$84,4,FALSE),0.4) -> 0.5 | T3: =R3*S3 -> 216 | U3: =T3/30 -> 7.2 | V3: =U3*0.625 -> 4.5 | W3: =IFERROR(VLOOKUP($L3,KEY!$A$13:$G$84,7,FALSE),18) -> 28 | X3: 10 | Y3: 6500 | Z3: 105000 | AA3: =Y3*O3*N3 -> 42250 | AB3: =(AA3/1000)*X3 -> 422.5 | AC3: =Z3*V3 -> 472500 | AD3: =(AC3/1000)*W3 -> 13230 | AE3: =SUM(AB3,AD3) -> 13652.5 | AF3: =AC3+AA3 -> 514750 | AG3: =IF(AF3=0,0,AE3/AF3*1000) -> 26.522584
A4: Mens | B4: Basketball | D4: Home | E4: Non-Conference | F4: Loyola (Md.) | H4: Patriot | I4: 11/12/2024 | J4: Tue | K4: 7:00 PM | L4: ESPN+ | M4: Streaming | N4: =KEY!$C$2 -> 0.65 | O4: =KEY!$D$2 -> 10 | P4: =KEY!$B$2 -> 7200 | Q4: =KEY!$E$2 -> 0.06 | R4: =P4*Q4 -> 432 | S4: =IFERROR(VLOOKUP($L4,KEY!$A$13:$G$84,4,FALSE),0.4) -> 0.4 | T4: =R4*S4 -> 172.8 | U4: =T4/30 -> 5.76 | V4: =U4*0.625 -> 3.6 | W4: =IFERROR(VLOOKUP($L4,KEY!$A$13:$G$84,7,FALSE),18) -> 18 | X4: 10 | Y4: 350 | Z4: 1500 | AA4: =Y4*O4*N4 -> 2275 | AB4: =(AA4/1000)*X4 -> 22.75 | AC4: =Z4*V4 -> 5400 | AD4: =(AC4/1000)*W4 -> 97.2 | AE4: =SUM(AB4,AD4) -> 119.95 | AF4: =AC4+AA4 -> 7675 | AG4: =IF(AF4=0,0,AE4/AF4*1000) -> 15.628664
A5: Mens | B5: Basketball | D5: Away | E5: Non-Conference | F5: Morgan State | H5: MEAC | I5: 11/16/2024 | J5: Sat | K5: 11:00 AM | L5: ESPN+ | M5: Streaming | N5: =KEY!$C$2 -> 0.65 | O5: =KEY!$D$2 -> 10 | P5: =KEY!$B$2 -> 7200 | Q5: =KEY!$E$2 -> 0.06 | R5: =P5*Q5 -> 432 | S5: =IFERROR(VLOOKUP($L5,KEY!$A$13:$G$84,4,FALSE),0.4) -> 0.4 | T5: =R5*S5 -> 172.8 | U5: =T5/30 -> 5.76 | V5: =U5*0.625 -> 3.6 | W5: =IFERROR(VLOOKUP($L5,KEY!$A$13:$G$84,7,FALSE),18) -> 18 | X5: 10 | Y5: 1200 | Z5: 1500 | AA5: =Y5*O5*N5 -> 7800 | AB5: =(AA5/1000)*X5 -> 78 | AC5: =Z5*V5 -> 5400 | AD5: =(AC5/1000)*W5 -> 97.2 | AE5: =SUM(AB5,AD5) -> 175.2 | AF5: =AC5+AA5 -> 13200 | AG5: =IF(AF5=0,0,AE5/AF5*1000) -> 13.272727
A6: Mens | B6: Basketball | D6: Away | E6: Non-Conference | F6: George Washington | H6: A10 | I6: 11/18/2024 | J6: Mon | K6: 7:00 PM | L6: ESPN+ | M6: Streaming | N6: =KEY!$C$2 -> 0.65 | O6: =KEY!$D$2 -> 10 | P6: =KEY!$B$2 -> 7200 | Q6: =KEY!$E$2 -> 0.06 | R6: =P6*Q6 -> 432 | S6: =IFERROR(VLOOKUP($L6,KEY!$A$13:$G$84,4,FALSE),0.4) -> 0.4 | T6: =R6*S6 -> 172.8 | U6: =T6/30 -> 5.76 | V6: =U6*0.625 -> 3.6 | W6: =IFERROR(VLOOKUP($L6,KEY!$A$13:$G$84,7,FALSE),18) -> 18 | X6: 10 | Y6: 1800 | Z6: 1500 | AA6: =Y6*O6*N6 -> 11700 | AB6: =(AA6/1000)*X6 -> 117 | AC6: =Z6*V6 -> 5400 | AD6: =(AC6/1000)*W6 -> 97.2 | AE6: =SUM(AB6,AD6) -> 214.2 | AF6: =AC6+AA6 -> 17100 | AG6: =IF(AF6=0,0,AE6/AF6*1000) -> 12.526316
A7: Mens | B7: Basketball | D7: Away | E7: Non-Conference | F7: Bucknell | H7: Patriot | I7: 11/21/2024 | J7: Thu | K7: 7:00 PM | L7: ESPN+ | M7: Streaming | N7: =KEY!$C$2 -> 0.65 | O7: =KEY!$D$2 -> 10 | P7: =KEY!$B$2 -> 7200 | Q7: =KEY!$E$2 -> 0.06 | R7: =P7*Q7 -> 432 | S7: =IFERROR(VLOOKUP($L7,KEY!$A$13:$G$84,4,FALSE),0.4) -> 0.4 | T7: =R7*S7 -> 172.8 | U7: =T7/30 -> 5.76 | V7: =U7*0.625 -> 3.6 | W7: =IFERROR(VLOOKUP($L7,KEY!$A$13:$G$84,7,FALSE),18) -> 18 | X7: 10 | Y7: 1100 | Z7: 1500 | AA7: =Y7*O7*N7 -> 7150 | AB7: =(AA7/1000)*X7 -> 71.5 | AC7: =Z7*V7 -> 5400 | AD7: =(AC7/1000)*W7 -> 97.2 | AE7: =SUM(AB7,AD7) -> 168.7 | AF7: =AC7+AA7 -> 12550 | AG7: =IF(AF7=0,0,AE7/AF7*1000) -> 13.442231
A8: Mens | B8: Basketball | D8: Away | E8: Non-Conference | F8: Cleveland State | H8: Horizon | I8: 11/26/2024 | J8: Tue | K8: 6:00 PM | L8: ESPN+ | M8: Streaming | N8: =KEY!$C$2 -> 0.65 | O8: =KEY!$D$2 -> 10 | P8: =KEY!$B$2 -> 7200 | Q8: =KEY!$E$2 -> 0.06 | R8: =P8*Q8 -> 432 | S8: =IFERROR(VLOOKUP($L8,KEY!$A$13:$G$84,4,FALSE),0.4) -> 0.4 | T8: =R8*S8 -> 172.8 | U8: =T8/30 -> 5.76 | V8: =U8*0.625 -> 3.6 | W8: =IFERROR(VLOOKUP($L8,KEY!$A$13:$G$84,7,FALSE),18) -> 18 | X8: 10 | Y8: 1500 | Z8: 1500 | AA8: =Y8*O8*N8 -> 9750 | AB8: =(AA8/1000)*X8 -> 97.5 | AC8: =Z8*V8 -> 5400 | AD8: =(AC8/1000)*W8 -> 97.2 | AE8: =SUM(AB8,AD8) -> 194.7 | AF8: =AC8+AA8 -> 15150 | AG8: =IF(AF8=0,0,AE8/AF8*1000) -> 12.851485
A9: Mens | B9: Basketball | D9: Neutral | E9: Cleveland State Thanksgiving | F9: Morehead State | H9: OVC | I9: 11/27/2024 | J9: Wed | K9: 4:00 PM | L9: ESPN+ | M9: Streaming | N9: =KEY!$C$2 -> 0.65 | O9: =KEY!$D$2 -> 10 | P9: =KEY!$B$2 -> 7200 | Q9: =KEY!$E$2 -> 0.06 | R9: =P9*Q9 -> 432 | S9: =IFERROR(VLOOKUP($L9,KEY!$A$13:$G$84,4,FALSE),0.4) -> 0.4 | T9: =R9*S9 -> 172.8 | U9: =T9/30 -> 5.76 | V9: =U9*0.625 -> 3.6 | W9: =IFERROR(VLOOKUP($L9,KEY!$A$13:$G$84,7,FALSE),18) -> 18 | X9: 10 | Y9: 400 | Z9: 1500 | AA9: =Y9*O9*N9 -> 2600 | AB9: =(AA9/1000)*X9 -> 26 | AC9: =Z9*V9 -> 5400 | AD9: =(AC9/1000)*W9 -> 97.2 | AE9: =SUM(AB9,AD9) -> 123.2 | AF9: =AC9+AA9 -> 8000 | AG9: =IF(AF9=0,0,AE9/AF9*1000) -> 15.4
A10: Mens | B10: Basketball | D10: Away | E10: Non-Conference | F10: UMass | H10: A10 | I10: 12/1/2024 | J10: Sun | K10: 12:00 PM | L10: ESPN+ | M10: Streaming | N10: =KEY!$C$2 -> 0.65 | O10: =KEY!$D$2 -> 10 | P10: =KEY!$B$2 -> 7200 | Q10: =KEY!$E$2 -> 0.06 | R10: =P10*Q10 -> 432 | S10: =IFERROR(VLOOKUP($L10,KEY!$A$13:$G$84,4,FALSE),0.4) -> 0.4 | T10: =R10*S10 -> 172.8 | U10: =T10/30 -> 5.76 | V10: =U10*0.625 -> 3.6 | W10: =IFERROR(VLOOKUP($L10,KEY!$A$13:$G$84,7,FALSE),18) -> 18 | X10: 10 | Y10: 3200 | Z10: 1500 | AA10: =Y10*O10*N10 -> 20800 | AB10: =(AA10/1000)*X10 -> 208 | AC10: =Z10*V10 -> 5400 | AD10: =(AC10/1000)*W10 -> 97.2 | AE10: =SUM(AB10,AD10) -> 305.2 | AF10: =AC10+AA10 -> 26200 | AG10: =IF(AF10=0,0,AE10/AF10*1000) -> 11.648855
A11: Mens | B11: Basketball | D11: Away | E11: Non-Conference | F11: Seton Hall | H11: Big East | I11: 12/4/2024 | J11: Wed | K11: 8:30 PM | L11: FS1 | M11: National Linear | N11: =KEY!$C$2 -> 0.65 | O11: =KEY!$D$2 -> 10 | P11: =KEY!$B$2 -> 7200 | Q11: =KEY!$E$2 -> 0.06 | R11: =P11*Q11 -> 432 | S11: =IFERROR(VLOOKUP($L11,KEY!$A$13:$G$84,4,FALSE),0.4) -> 0.5 | T11: =R11*S11 -> 216 | U11: =T11/30 -> 7.2 | V11: =U11*0.625 -> 4.5 | W11: =IFERROR(VLOOKUP($L11,KEY!$A$13:$G$84,7,FALSE),18) -> 28 | X11: 10 | Y11: 8500 | Z11: 75000 | AA11: =Y11*O11*N11 -> 55250 | AB11: =(AA11/1000)*X11 -> 552.5 | AC11: =Z11*V11 -> 337500 | AD11: =(AC11/1000)*W11 -> 9450 | AE11: =SUM(AB11,AD11) -> 10002.5 | AF11: =AC11+AA11 -> 392750 | AG11: =IF(AF11=0,0,AE11/AF11*1000) -> 25.467855
A12: Mens | B12: Basketball | D12: Home | E12: Non-Conference | F12: Navy | H12: Patriot | I12: 12/7/2024 | J12: Sat | K12: 2:00 PM | L12: ESPN+ | M12: Streaming | N12: =KEY!$C$2 -> 0.65 | O12: =KEY!$D$2 -> 10 | P12: =KEY!$B$2 -> 7200 | Q12: =KEY!$E$2 -> 0.06 | R12: =P12*Q12 -> 432 | S12: =IFERROR(VLOOKUP($L12,KEY!$A$13:$G$84,4,FALSE),0.4) -> 0.4 | T12: =R12*S12 -> 172.8 | U12: =T12/30 -> 5.76 | V12: =U12*0.625 -> 3.6 | W12: =IFERROR(VLOOKUP($L12,KEY!$A$13:$G$84,7,FALSE),18) -> 18 | X12: 10 | Y12: 548 | Z12: 1500 | AA12: =Y12*O12*N12 -> 3562 | AB12: =(AA12/1000)*X12 -> 35.62 | AC12: =Z12*V12 -> 5400 | AD12: =(AC12/1000)*W12 -> 97.2 | AE12: =SUM(AB12,AD12) -> 132.82 | AF12: =AC12+AA12 -> 8962 | AG12: =IF(AF12=0,0,AE12/AF12*1000) -> 14.820353
A13: Mens | B13: Basketball | D13: Away | E13: Non-Conference | F13: Delaware State | H13: MEAC | I13: 12/11/2024 | J13: Wed | K13: 7:00 PM | L13: ESPN+ | M13: Streaming | N13: =KEY!$C$2 -> 0.65 | O13: =KEY!$D$2 -> 10 | P13: =KEY!$B$2 -> 7200 | Q13: =KEY!$E$2 -> 0.06 | R13: =P13*Q13 -> 432 | S13: =IFERROR(VLOOKUP($L13,KEY!$A$13:$G$84,4,FALSE),0.4) -> 0.4 | T13: =R13*S13 -> 172.8 | U13: =T13/30 -> 5.76 | V13: =U13*0.625 -> 3.6 | W13: =IFERROR(VLOOKUP($L13,KEY!$A$13:$G$84,7,FALSE),18) -> 18 | X13: 10 | Y13: 600 | Z13: 1500 | AA13: =Y13*O13*N13 -> 3900 | AB13: =(AA13/1000)*X13 -> 39 | AC13: =Z13*V13 -> 5400 | AD13: =(AC13/1000)*W13 -> 97.2 | AE13: =SUM(AB13,AD13) -> 136.2 | AF13: =AC13+AA13 -> 9300 | AG13: =IF(AF13=0,0,AE13/AF13*1000) -> 14.645161
A14: Mens | B14: Basketball | D14: Home | E14: Non-Conference | F14: Wagner | H14: NEC | I14: 12/14/2024 | J14: Sat | K14: 4:00 PM | L14: ESPN+ | M14: Streaming | N14: =KEY!$C$2 -> 0.65 | O14: =KEY!$D$2 -> 10 | P14: =KEY!$B$2 -> 7200 | Q14: =KEY!$E$2 -> 0.06 | R14: =P14*Q14 -> 432 | S14: =IFERROR(VLOOKUP($L14,KEY!$A$13:$G$84,4,FALSE),0.4) -> 0.4 | T14: =R14*S14 -> 172.8 | U14: =T14/30 -> 5.76 | V14: =U14*0.625 -> 3.6 | W14: =IFERROR(VLOOKUP($L14,KEY!$A$13:$G$84,7,FALSE),18) -> 18 | X14: 10 | Y14: 400 | Z14: 1500 | AA14: =Y14*O14*N14 -> 2600 | AB14: =(AA14/1000)*X14 -> 26 | AC14: =Z14*V14 -> 5400 | AD14: =(AC14/1000)*W14 -> 97.2 | AE14: =SUM(AB14,AD14) -> 123.2 | AF14: =AC14+AA14 -> 8000 | AG14: =IF(AF14=0,0,AE14/AF14*1000) -> 15.4
A15: Mens | B15: Basketball | D15: Away | E15: Non-Conference | F15: Washington | H15: Pac-12 | I15: 12/29/2024 | J15: Sun | K15: 3:00 PM | L15: Pac-12 Network | M15: Streaming | N15: =KEY!$C$2 -> 0.65 | O15: =KEY!$D$2 -> 10 | P15: =KEY!$B$2 -> 7200 | Q15: =KEY!$E$2 -> 0.06 | R15: =P15*Q15 -> 432 | S15: =IFERROR(VLOOKUP($L15,KEY!$A$13:$G$84,4,FALSE),0.4) -> 0.4 | T15: =R15*S15 -> 172.8 | U15: =T15/30 -> 5.76 | V15: =U15*0.625 -> 3.6 | W15: =IFERROR(VLOOKUP($L15,KEY!$A$13:$G$84,7,FALSE),18) -> 18 | X15: 10 | Y15: 4500 | Z15: 50000 | AA15: =Y15*O15*N15 -> 29250 | AB15: =(AA15/1000)*X15 -> 292.5 | AC15: =Z15*V15 -> 180000 | AD15: =(AC15/1000)*W15 -> 3240 | AE15: =SUM(AB15,AD15) -> 3532.5 | AF15: =AC15+AA15 -> 209250 | AG15: =IF(AF15=0,0,AE15/AF15*1000) -> 16.88172
A16: Mens | B16: Basketball | D16: Home | E16: Non-Conference | F16: Medgar Evers | I16: 1/4/2025 | J16: Sat | K16: 2:00 PM | L16: ESPN+ | M16: Streaming | N16: =KEY!$C$2 -> 0.65 | O16: =KEY!$D$2 -> 10 | P16: =KEY!$B$2 -> 7200 | Q16: =KEY!$E$2 -> 0.06 | R16: =P16*Q16 -> 432 | S16: =IFERROR(VLOOKUP($L16,KEY!$A$13:$G$84,4,FALSE),0.4) -> 0.4 | T16: =R16*S16 -> 172.8 | U16: =T16/30 -> 5.76 | V16: =U16*0.625 -> 3.6 | W16: =IFERROR(VLOOKUP($L16,KEY!$A$13:$G$84,7,FALSE),18) -> 18 | X16: 10 | Y16: 200 | Z16: 1500 | AA16: =Y16*O16*N16 -> 1300 | AB16: =(AA16/1000)*X16 -> 13 | AC16: =Z16*V16 -> 5400 | AD16: =(AC16/1000)*W16 -> 97.2 | AE16: =SUM(AB16,AD16) -> 110.2 | AF16: =AC16+AA16 -> 6700 | AG16: =IF(AF16=0,0,AE16/AF16*1000) -> 16.447761
A17: Mens | B17: Basketball | D17: Home | E17: America East | F17: UMBC | H17: America East | I17: 1/9/2025 | J17: Thu | K17: 7:00 PM | L17: ESPN+ | M17: Streaming | N17: =KEY!$C$2 -> 0.65 | O17: =KEY!$D$2 -> 10 | P17: =KEY!$B$2 -> 7200 | Q17: =KEY!$E$2 -> 0.06 | R17: =P17*Q17 -> 432 | S17: =IFERROR(VLOOKUP($L17,KEY!$A$13:$G$84,4,FALSE),0.4) -> 0.4 | T17: =R17*S17 -> 172.8 | U17: =T17/30 -> 5.76 | V17: =U17*0.625 -> 3.6 | W17: =IFERROR(VLOOKUP($L17,KEY!$A$13:$G$84,7,FALSE),18) -> 18 | X17: 10 | Y17: 450 | Z17: 1500 | AA17: =Y17*O17*N17 -> 2925 | AB17: =(AA17/1000)*X17 -> 29.25 | AC17: =Z17*V17 -> 5400 | AD17: =(AC17/1000)*W17 -> 97.2 | AE17: =SUM(AB17,AD17) -> 126.45 | AF17: =AC17+AA17 -> 8325 | AG17: =IF(AF17=0,0,AE17/AF17*1000) -> 15.189189
A18: Mens | B18: Basketball | D18: Away | E18: America East | F18: UMass Lowell | H18: America East | I18: 1/11/2025 | J18: Sat | K18: 1:00 PM | L18: ESPN+ | M18: Streaming | N18: =KEY!$C$2 -> 0.65 | O18: =KEY!$D$2 -> 10 | P18: =KEY!$B$2 -> 7200 | Q18: =KEY!$E$2 -> 0.06 | R18: =P18*Q18 -> 432 | S18: =IFERROR(VLOOKUP($L18,KEY!$A$13:$G$84,4,FALSE),0.4) -> 0.4 | T18: =R18*S18 -> 172.8 | U18: =T18/30 -> 5.76 | V18: =U18*0.625 -> 3.6 | W18: =IFERROR(VLOOKUP($L18,KEY!$A$13:$G$84,7,FALSE),18) -> 18 | X18: 10 | Y18: 1100 | Z18: 1500 | AA18: =Y18*O18*N18 -> 7150 | AB18: =(AA18/1000)*X18 -> 71.5 | AC18: =Z18*V18 -> 5400 | AD18: =(AC18/1000)*W18 -> 97.2 | AE18: =SUM(AB18,AD18) -> 168.7 | AF18: =AC18+AA18 -> 12550 | AG18: =IF(AF18=0,0,AE18/AF18*1000) -> 13.442231
A19: Mens | B19: Basketball | D19: Home | E19: America East | F19: Maine | H19: America East | I19: 1/16/2025 | J19: Thu | K19: 11:00 AM | L19: ESPN+ | M19: Streaming | N19: =KEY!$C$2 -> 0.65 | O19: =KEY!$D$2 -> 10 | P19: =KEY!$B$2 -> 7200 | Q19: =KEY!$E$2 -> 0.06 | R19: =P19*Q19 -> 432 | S19: =IFERROR(VLOOKUP($L19,KEY!$A$13:$G$84,4,FALSE),0.4) -> 0.4 | T19: =R19*S19 -> 172.8 | U19: =T19/30 -> 5.76 | V19: =U19*0.625 -> 3.6 | W19: =IFERROR(VLOOKUP($L19,KEY!$A$13:$G$84,7,FALSE),18) -> 18 | X19: 10 | Y19: 550 | Z19: 1500 | AA19: =Y19*O19*N19 -> 3575 | AB19: =(AA19/1000)*X19 -> 35.75 | AC19: =Z19*V19 -> 5400 | AD19: =(AC19/1000)*W19 -> 97.2 | AE19: =SUM(AB19,AD19) -> 132.95 | AF19: =AC19+AA19 -> 8975 | AG19: =IF(AF19=0,0,AE19/AF19*1000) -> 14.81337
A20: Mens | B20: Basketball | D20: Home | E20: America East | F20: New Hampshire | H20: America East | I20: 1/18/2025 | J20: Sat | K20: 3:00 PM | L20: ESPN+ | M20: Streaming | N20: =KEY!$C$2 -> 0.65 | O20: =KEY!$D$2 -> 10 | P20: =KEY!$B$2 -> 7200 | Q20: =KEY!$E$2 -> 0.06 | R20: =P20*Q20 -> 432 | S20: =IFERROR(VLOOKUP($L20,KEY!$A$13:$G$84,4,FALSE),0.4) -> 0.4 | T20: =R20*S20 -> 172.8 | U20: =T20/30 -> 5.76 | V20: =U20*0.625 -> 3.6 | W20: =IFERROR(VLOOKUP($L20,KEY!$A$13:$G$84,7,FALSE),18) -> 18 | X20: 10 | Y20: 500 | Z20: 1500 | AA20: =Y20*O20*N20 -> 3250 | AB20: =(AA20/1000)*X20 -> 32.5 | AC20: =Z20*V20 -> 5400 | AD20: =(AC20/1000)*W20 -> 97.2 | AE20: =SUM(AB20,AD20) -> 129.7 | AF20: =AC20+AA20 -> 8650 | AG20: =IF(AF20=0,0,AE20/AF20*1000) -> 14.99422
A21: Mens | B21: Basketball | D21: Away | E21: America East | F21: Vermont | H21: America East | I21: 1/23/2025 | J21: Thu | K21: 7:00 PM | L21: ESPN+ | M21: Streaming | N21: =KEY!$C$2 -> 0.65 | O21: =KEY!$D$2 -> 10 | P21: =KEY!$B$2 -> 7200 | Q21: =KEY!$E$2 -> 0.06 | R21: =P21*Q21 -> 432 | S21: =IFERROR(VLOOKUP($L21,KEY!$A$13:$G$84,4,FALSE),0.4) -> 0.4 | T21: =R21*S21 -> 172.8 | U21: =T21/30 -> 5.76 | V21: =U21*0.625 -> 3.6 | W21: =IFERROR(VLOOKUP($L21,KEY!$A$13:$G$84,7,FALSE),18) -> 18 | X21: 10 | Y21: 2200 | Z21: 1500 | AA21: =Y21*O21*N21 -> 14300 | AB21: =(AA21/1000)*X21 -> 143 | AC21: =Z21*V21 -> 5400 | AD21: =(AC21/1000)*W21 -> 97.2 | AE21: =SUM(AB21,AD21) -> 240.2 | AF21: =AC21+AA21 -> 19700 | AG21: =IF(AF21=0,0,AE21/AF21*1000) -> 12.192893
A22: Mens | B22: Basketball | D22: Away | E22: America East | F22: UAlbany | H22: America East | I22: 1/25/2025 | J22: Sat | K22: 4:00 PM | L22: ESPN+ | M22: Streaming | N22: =KEY!$C$2 -> 0.65 | O22: =KEY!$D$2 -> 10 | P22: =KEY!$B$2 -> 7200 | Q22: =KEY!$E$2 -> 0.06 | R22: =P22*Q22 -> 432 | S22: =IFERROR(VLOOKUP($L22,KEY!$A$13:$G$84,4,FALSE),0.4) -> 0.4 | T22: =R22*S22 -> 172.8 | U22: =T22/30 -> 5.76 | V22: =U22*0.625 -> 3.6 | W22: =IFERROR(VLOOKUP($L22,KEY!$A$13:$G$84,7,FALSE),18) -> 18 | X22: 10 | Y22: 2100 | Z22: 1500 | AA22: =Y22*O22*N22 -> 13650 | AB22: =(AA22/1000)*X22 -> 136.5 | AC22: =Z22*V22 -> 5400 | AD22: =(AC22/1000)*W22 -> 97.2 | AE22: =SUM(AB22,AD22) -> 233.7 | AF22: =AC22+AA22 -> 19050 | AG22: =IF(AF22=0,0,AE22/AF22*1000) -> 12.267717
A23: Mens | B23: Basketball | D23: Home | E23: America East | F23: UMass Lowell | H23: America East | I23: 1/30/2025 | J23: Thu | K23: 7:00 PM | L23: ESPN+ | M23: Streaming | N23: =KEY!$C$2 -> 0.65 | O23: =KEY!$D$2 -> 10 | P23: =KEY!$B$2 -> 7200 | Q23: =KEY!$E$2 -> 0.06 | R23: =P23*Q23 -> 432 | S23: =IFERROR(VLOOKUP($L23,KEY!$A$13:$G$84,4,FALSE),0.4) -> 0.4 | T23: =R23*S23 -> 172.8 | U23: =T23/30 -> 5.76 | V23: =U23*0.625 -> 3.6 | W23: =IFERROR(VLOOKUP($L23,KEY!$A$13:$G$84,7,FALSE),18) -> 18 | X23: 10 | Y23: 480 | Z23: 1500 | AA23: =Y23*O23*N23 -> 3120 | AB23: =(AA23/1000)*X23 -> 31.2 | AC23: =Z23*V23 -> 5400 | AD23: =(AC23/1000)*W23 -> 97.2 | AE23: =SUM(AB23,AD23) -> 128.4 | AF23: =AC23+AA23 -> 8520 | AG23: =IF(AF23=0,0,AE23/AF23*1000) -> 15.070423
A24: Mens | B24: Basketball | D24: Home | E24: America East | F24: Bryant | H24: America East | I24: 2/1/2025 | J24: Sat | K24: 2:00 PM | L24: ESPN+ | M24: Streaming | N24: =KEY!$C$2 -> 0.65 | O24: =KEY!$D$2 -> 10 | P24: =KEY!$B$2 -> 7200 | Q24: =KEY!$E$2 -> 0.06 | R24: =P24*Q24 -> 432 | S24: =IFERROR(VLOOKUP($L24,KEY!$A$13:$G$84,4,FALSE),0.4) -> 0.4 | T24: =R24*S24 -> 172.8 | U24: =T24/30 -> 5.76 | V24: =U24*0.625 -> 3.6 | W24: =IFERROR(VLOOKUP($L24,KEY!$A$13:$G$84,7,FALSE),18) -> 18 | X24: 10 | Y24: 520 | Z24: 1500 | AA24: =Y24*O24*N24 -> 3380 | AB24: =(AA24/1000)*X24 -> 33.8 | AC24: =Z24*V24 -> 5400 | AD24: =(AC24/1000)*W24 -> 97.2 | AE24: =SUM(AB24,AD24) -> 131 | AF24: =AC24+AA24 -> 8780 | AG24: =IF(AF24=0,0,AE24/AF24*1000) -> 14.920273
A25: Mens | B25: Basketball | D25: Away | E25: America East | F25: Maine | H25: America East | I25: 2/6/2025 | J25: Thu | K25: 6:00 PM | L25: ESPN+ | M25: Streaming | N25: =KEY!$C$2 -> 0.65 | O25: =KEY!$D$2 -> 10 | P25: =KEY!$B$2 -> 7200 | Q25: =KEY!$E$2 -> 0.06 | R25: =P25*Q25 -> 432 | S25: =IFERROR(VLOOKUP($L25,KEY!$A$13:$G$84,4,FALSE),0.4) -> 0.4 | T25: =R25*S25 -> 172.8 | U25: =T25/30 -> 5.76 | V25: =U25*0.625 -> 3.6 | W25: =IFERROR(VLOOKUP($L25,KEY!$A$13:$G$84,7,FALSE),18) -> 18 | X25: 10 | Y25: 1400 | Z25: 1500 | AA25: =Y25*O25*N25 -> 9100 | AB25: =(AA25/1000)*X25 -> 91 | AC25: =Z25*V25 -> 5400 | AD25: =(AC25/1000)*W25 -> 97.2 | AE25: =SUM(AB25,AD25) -> 188.2 | AF25: =AC25+AA25 -> 14500 | AG25: =IF(AF25=0,0,AE25/AF25*1000) -> 12.97931
A26: Mens | B26: Basketball | D26: Away | E26: America East | F26: New Hampshire | H26: America East | I26: 2/8/2025 | J26: Sat | K26: 1:00 PM | L26: ESPN+ | M26: Streaming | N26: =KEY!$C$2 -> 0.65 | O26: =KEY!$D$2 -> 10 | P26: =KEY!$B$2 -> 7200 | Q26: =KEY!$E$2 -> 0.06 | R26: =P26*Q26 -> 432 | S26: =IFERROR(VLOOKUP($L26,KEY!$A$13:$G$84,4,FALSE),0.4) -> 0.4 | T26: =R26*S26 -> 172.8 | U26: =T26/30 -> 5.76 | V26: =U26*0.625 -> 3.6 | W26: =IFERROR(VLOOKUP($L26,KEY!$A$13:$G$84,7,FALSE),18) -> 18 | X26: 10 | Y26: 1200 | Z26: 1500 | AA26: =Y26*O26*N26 -> 7800 | AB26: =(AA26/1000)*X26 -> 78 | AC26: =Z26*V26 -> 5400 | AD26: =(AC26/1000)*W26 -> 97.2 | AE26: =SUM(AB26,AD26) -> 175.2 | AF26: =AC26+AA26 -> 13200 | AG26: =IF(AF26=0,0,AE26/AF26*1000) -> 13.272727
A27: Mens | B27: Basketball | D27: Away | E27: America East | F27: Bryant | H27: America East | I27: 2/13/2025 | J27: Thu | K27: 6:00 PM | L27: ESPN+ | M27: Streaming | N27: =KEY!$C$2 -> 0.65 | O27: =KEY!$D$2 -> 10 | P27: =KEY!$B$2 -> 7200 | Q27: =KEY!$E$2 -> 0.06 | R27: =P27*Q27 -> 432 | S27: =IFERROR(VLOOKUP($L27,KEY!$A$13:$G$84,4,FALSE),0.4) -> 0.4 | T27: =R27*S27 -> 172.8 | U27: =T27/30 -> 5.76 | V27: =U27*0.625 -> 3.6 | W27: =IFERROR(VLOOKUP($L27,KEY!$A$13:$G$84,7,FALSE),18) -> 18 | X27: 10 | Y27: 1800 | Z27: 1500 | AA27: =Y27*O27*N27 -> 11700 | AB27: =(AA27/1000)*X27 -> 117 | AC27: =Z27*V27 -> 5400 | AD27: =(AC27/1000)*W27 -> 97.2 | AE27: =SUM(AB27,AD27) -> 214.2 | AF27: =AC27+AA27 -> 17100 | AG27: =IF(AF27=0,0,AE27/AF27*1000) -> 12.526316
A28: Mens | B28: Basketball | D28: Home | E28: America East | F28: Binghamton | H28: America East | I28: 2/15/2025 | J28: Sat | K28: 2:00 PM | L28: ESPN+ | M28: Streaming | N28: =KEY!$C$2 -> 0.65 | O28: =KEY!$D$2 -> 10 | P28: =KEY!$B$2 -> 7200 | Q28: =KEY!$E$2 -> 0.06 | R28: =P28*Q28 -> 432 | S28: =IFERROR(VLOOKUP($L28,KEY!$A$13:$G$84,4,FALSE),0.4) -> 0.4 | T28: =R28*S28 -> 172.8 | U28: =T28/30 -> 5.76 | V28: =U28*0.625 -> 3.6 | W28: =IFERROR(VLOOKUP($L28,KEY!$A$13:$G$84,7,FALSE),18) -> 18 | X28: 10 | Y28: 540 | Z28: 1500 | AA28: =Y28*O28*N28 -> 3510 | AB28: =(AA28/1000)*X28 -> 35.1 | AC28: =Z28*V28 -> 5400 | AD28: =(AC28/1000)*W28 -> 97.2 | AE28: =SUM(AB28,AD28) -> 132.3 | AF28: =AC28+AA28 -> 8910 | AG28: =IF(AF28=0,0,AE28/AF28*1000) -> 14.848485
... A61: Womens | B61: Basketball | D61: Away | E61: America East | F61: UAlbany | H61: America East | I61: 3/1/2025 | J61: Sat | K61: 7:00 PM | L61: ESPN+ | M61: Streaming | N61: =KEY!$C$2 -> 0.65 | O61: =KEY!$D$2 -> 10 | P61: =KEY!$B$2 -> 7200 | Q61: =KEY!$E$2 -> 0.06 | R61: =P61*Q61 -> 432 | S61: =IFERROR(VLOOKUP($L61,KEY!$A$13:$G$84,4,FALSE),0.4) -> 0.4 | T61: =R61*S61 -> 172.8 | U61: =T61/30 -> 5.76 | V61: =U61*0.625 -> 3.6 | W61: =IFERROR(VLOOKUP($L61,KEY!$A$13:$G$84,7,FALSE),18) -> 18 | X61: 10 | Y61: 1500 | Z61: 1000 | AA61: =Y61*O61*N61 -> 9750 | AB61: =(AA61/1000)*X61 -> 97.5 | AC61: =Z61*V61 -> 3600 | AD61: =(AC61/1000)*W61 -> 64.8 | AE61: =SUM(AB61,AD61) -> 162.3 | AF61: =AC61+AA61 -> 13350 | AG61: =IF(AF61=0,0,AE61/AF61*1000) -> 12.157303
A62: Womens | B62: Basketball | D62: Neutral | E62: America East Quarterfinals | F62: Maine | G62: 4 | H62: America East | I62: 3/6/2025 | J62: Thu | K62: 6:00 PM | L62: ESPN+ | M62: Streaming | N62: =KEY!$C$2 -> 0.65 | O62: =KEY!$D$2 -> 10 | P62: =KEY!$B$2 -> 7200 | Q62: =KEY!$E$2 -> 0.06 | R62: =P62*Q62 -> 432 | S62: =IFERROR(VLOOKUP($L62,KEY!$A$13:$G$84,4,FALSE),0.4) -> 0.4 | T62: =R62*S62 -> 172.8 | U62: =T62/30 -> 5.76 | V62: =U62*0.625 -> 3.6 | W62: =IFERROR(VLOOKUP($L62,KEY!$A$13:$G$84,7,FALSE),18) -> 18 | X62: 10 | Y62: 1800 | Z62: 1200 | AA62: =Y62*O62*N62 -> 11700 | AB62: =(AA62/1000)*X62 -> 117 | AC62: =Z62*V62 -> 4320 | AD62: =(AC62/1000)*W62 -> 77.76 | AE62: =SUM(AB62,AD62) -> 194.76 | AF62: =AC62+AA62 -> 16020 | AG62: =IF(AF62=0,0,AE62/AF62*1000) -> 12.157303

Sheet Incremental Assets
A1: asset name | B1: Asset Category | C1: asset type | D1: Channel | E1: gender | F1: category | G1: imp | H1: value | I1: ccv | J1: Annual spec/social followers/web traffic/social impressions | K1: exp | L1: imp/ spec | M1: imp/viewer | N1: avail per game/month | O1: Total Availability | P1: dur/ game (Sec) | Q1: Duration Index (dii) (Sec)/frequency index | R1: # games/ posts | S1: CPM | T1: Notes
A2: Commercial Units (30 sec) | B2: Incremental Asset Package | C2: Streaming | D2: ESPN+ | E2: Men's | F2: Basketball | G2: =I2*O2*M2 -> 273000 | H2: =G2/1000*S2 -> 4095 | I2: 1500 | M2: 2 | N2: 7 | O2: =N2*R2 -> 91 | R2: 13 | S2: 15
A3: Commercial Units (30 sec) | B3: Incremental Asset Package | C3: Streaming | D3: ESPN+ | E3: Women's | F3: Basketball | G3: =I3*O3*M3 -> 196000 | H3: =G3/1000*S3 -> 2940 | I3: 1000 | M3: 2 | N3: 7 | O3: =N3*R3 -> 98 | R3: 14 | S3: 15
A4: Sideline Banners (tv visible) | B4: Incremental Asset Package | C4: Streaming | D4: ESPN+ | E4: Men's | F4: Basketball | G4: =P4/Q4*I4*O4 -> 234000 | H4: =G4/1000*S4 -> 1170 | I4: 1500 | N4: 1 | O4: =N4*R4 -> 13 | P4: =(120*60)*0.05 -> 360 | Q4: 30 | R4: 13 | S4: 5
A5: Sideline Banners (tv visible) | B5: Incremental Asset Package | C5: Onsite | D5: Onsite | E5: Men's | F5: Basketball | G5: =J5*K5*L5*N5 -> 6018 | H5: =G5/1000*S5 -> 30.09 | J5: 6018 | K5: 0.5 | L5: 2 | N5: 1 | O5: =N5*R5 -> 13 | R5: 13 | S5: 5
A6: Sideline Banners (tv visible) | B6: Incremental Asset Package | C6: Streaming | D6: ESPN+ | E6: Women's | F6: Basketball | G6: =P6/Q6*I6*O6 -> 168000 | H6: =G6/1000*S6 -> 840 | I6: 1000 | N6: 1 | O6: =N6*R6 -> 14 | P6: =(120*60)*0.05 -> 360 | Q6: 30 | R6: 14 | S6: 5
A7: Sideline Banners (tv visible) | B7: Incremental Asset Package | C7: Onsite | D7: Onsite | E7: Women's | F7: Basketball | G7: =J7*K7*L7*N7 -> 3850 | H7: =G7/1000*S7 -> 19.25 | J7: 3850 | K7: 0.5 | L7: 2 | N7: 1 | O7: =N7*R7 -> 14 | R7: 14 | S7: 5
A8: Email Marketing Inclusion | B8: Incremental Asset Package | C8: Digital Inventory | D8: Email | E8: Mens/Womens | F8: Athletic Dept | G8: =J8*K8*R8 -> 1320000 | H8: =G8/1000*S8 -> 6600 | J8: 55000 | K8: 0.08 | N8: 1 | O8: =N8*R8 -> 300 | R8: 300 | S8: 5
A9: Web Banner Advertising | B9: Incremental Asset Package | C9: Digital Inventory | D9: Website | E9: Mens/Womens | F9: Athletic Dept | G9: =J9*K9*R9 -> 45000 | H9: =G9/1000*S9 -> 360 | J9: 450000 | K9: 0.1 | N9: 1 | O9: =N9*R9 -> 1 | R9: 1 | S9: 8
A10: Sponsored Social Media Series 1 Per Week During School Year | B10: Incremental Asset Package | C10: Social Media | D10: Instagram | E10: Mens/Womens | F10: Athletic Dept | G10: =J10*K10*R10 -> 123120 | H10: =G10/1000*S10 -> 2462.4 | J10: 8100 | K10: 0.38 | N10: 1 | O10: =N10*R10 -> 40 | R10: 40 | S10: 20
A11: Sponsored Social Media Series 1 Per Week During School Year | B11: Incremental Asset Package | C11: Social Media | D11: Facebook | E11: Mens/Womens | F11: Athletic Dept | G11: =J11*K11*R11 -> 78880 | H11: =G11/1000*S11 -> 788.8 | J11: 2900 | K11: 0.68 | N11: 1 | O11: =N11*R11 -> 40 | R11: 40 | S11: 10
A12: Sponsored Social Media Series 1 Per Week During School Year | B12: Incremental Asset Package | C12: Social Media | D12: Twitter/X | E12: Mens/Womens | F12: Athletic Dept | G12: =J12*K12*R12 -> 33200 | H12: =G12/1000*S12 -> 398.4 | J12: 16600 | K12: 0.05 | N12: 1 | O12: =N12*R12 -> 40 | R12: 40 | S12: 12

Sheet Incremental Assets W JP
A1: asset name | B1: Asset Category | C1: asset type | D1: Channel | E1: gender | F1: category | G1: imp | H1: value | I1: ccv | J1: Annual spec/social followers/web traffic/social impressions | K1: exp | L1: imp/ spec | M1: imp/viewer | N1: avail per game/month | O1: Total Availability | P1: dur/ game (Sec) | Q1: Duration Index (dii) (Sec)/frequency index | R1: # games/ posts | S1: CPM | T1: Notes
A2: Commercial Units (30 sec) | B2: Incremental Asset Package | C2: Streaming | D2: ESPN+ | E2: Men's | F2: Basketball | G2: =I2*O2*M2 -> 273000 | H2: =G2/1000*S2 -> 4095 | I2: 1500 | M2: 2 | N2: 7 | O2: =N2*R2 -> 91 | R2: 13 | S2: 15
A3: Commercial Units (30 sec) | B3: Incremental Asset Package | C3: Streaming | D3: ESPN+ | E3: Women's | F3: Basketball | G3: =I3*O3*M3 -> 196000 | H3: =G3/1000*S3 -> 2940 | I3: 1000 | M3: 2 | N3: 7 | O3: =N3*R3 -> 98 | R3: 14 | S3: 15
A4: Sideline Banners (tv visible) | B4: Incremental Asset Package | C4: Streaming | D4: ESPN+ | E4: Men's | F4: Basketball | G4: =P4/Q4*I4*O4 -> 234000 | H4: =G4/1000*S4 -> 1170 | I4: 1500 | N4: 1 | O4: =N4*R4 -> 13 | P4: =(120*60)*0.05 -> 360 | Q4: 30 | R4: 13 | S4: 5
A5: Sideline Banners (tv visible) | B5: Incremental Asset Package | C5: Onsite | D5: Onsite | E5: Men's | F5: Basketball | G5: =J5*K5*L5*N5 -> 6018 | H5: =G5/1000*S5 -> 30.09 | J5: 6018 | K5: 0.5 | L5: 2 | N5: 1 | O5: =N5*R5 -> 13 | R5: 13 | S5: 5
A6: Sideline Banners (tv visible) | B6: Incremental Asset Package | C6: Streaming | D6: ESPN+ | E6: Women's | F6: Basketball | G6: =P6/Q6*I6*O6 -> 168000 | H6: =G6/1000*S6 -> 840 | I6: 1000 | N6: 1 | O6: =N6*R6 -> 14 | P6: =(120*60)*0.05 -> 360 | Q6: 30 | R6: 14 | S6: 5
A7: Sideline Banners (tv visible) | B7: Incremental Asset Package | C7: Onsite | D7: Onsite | E7: Women's | F7: Basketball | G7: =J7*K7*L7*N7 -> 3850 | H7: =G7/1000*S7 -> 19.25 | J7: 3850 | K7: 0.5 | L7: 2 | N7: 1 | O7: =N7*R7 -> 14 | R7: 14 | S7: 5
A8: Email Marketing Inclusion | B8: Incremental Asset Package | C8: Digital Inventory | D8: Email | E8: Mens/Womens | F8: Athletic Dept | G8: =J8*K8*R8 -> 1320000 | H8: =G8/1000*S8 -> 6600 | J8: 55000 | K8: 0.08 | N8: 1 | O8: =N8*R8 -> 300 | R8: 300 | S8: 5
A9: Web Banner Advertising | B9: Incremental Asset Package | C9: Digital Inventory | D9: Website | E9: Mens/Womens | F9: Athletic Dept | G9: =J9*K9*R9 -> 45000 | H9: =G9/1000*S9 -> 360 | J9: 450000 | K9: 0.1 | N9: 1 | O9: =N9*R9 -> 1 | R9: 1 | S9: 8
A10: Sponsored Social Media Series 1 Per Week During School Year | B10: Incremental Asset Package | C10: Social Media | D10: Instagram | E10: Mens/Womens | F10: Athletic Dept | G10: =J10*K10*R10 -> 123120 | H10: =G10/1000*S10 -> 2462.4 | J10: 8100 | K10: 0.38 | N10: 1 | O10: =N10*R10 -> 40 | R10: 40 | S10: 20
A11: Sponsored Social Media Series 1 Per Week During School Year | B11: Incremental Asset Package | C11: Social Media | D11: Facebook | E11: Mens/Womens | F11: Athletic Dept | G11: =J11*K11*R11 -> 78880 | H11: =G11/1000*S11 -> 788.8 | J11: 2900 | K11: 0.68 | N11: 1 | O11: =N11*R11 -> 40 | R11: 40 | S11: 10
A12: Sponsored Social Media Series 1 Per Week During School Year | B12: Incremental Asset Package | C12: Social Media | D12: Twitter/X | E12: Mens/Womens | F12: Athletic Dept | G12: =J12*K12*R12 -> 33200 | H12: =G12/1000*S12 -> 398.4 | J12: 16600 | K12: 0.05 | N12: 1 | O12: =N12*R12 -> 40 | R12: 40 | S12: 12
A13: Jersey Patch | B13: Jersey Patch | C13: Streaming | D13: ESPN+ | E13: Men's | F13: Basketball | G13: 339167 | H13: 4601 | R13: 28 | S13: 18
A14: Jersey Patch | B14: Jersey Patch | C14: Broadcast | D14: FS1 | E14: Men's | F14: Basketball | G14: 907500 | H14: 23655 | R14: 2 | S14: 20
A15: Jersey Patch | B15: Jersey Patch | C15: Streaming | D15: Pac-12 Network | E15: Men's | F15: Basketball | G15: 209250 | H15: 3532.5 | R15: 1 | S15: 18
A16: Jersey Patch | B16: Jersey Patch | C16: Streaming | D16: ESPN+ | E16: Women's | F16: Basketball | G16: 224265 | H16: 3083.61 | R16: 29 | S16: 18
A17: Jersey Patch | B17: Jersey Patch | C17: Broadcast | D17: BTN | E17: Women's | F17: Basketball | G17: 88050 | H17: 1609.5 | R17: 1 | S17: 18
A18: Jersey Patch (Social Media) | B18: Jersey Patch Social Media | C18: Social Media | D18: Facebook | E18: Men's | F18: Basketball | G18: 84746.25 | H18: 847.4625 | S18: 10
A19: Jersey Patch (Social Media) | B19: Jersey Patch Social Media | C19: Social Media | D19: Instagram | E19: Men's | F19: Basketball | G19: 136710 | H19: 2734.2 | S19: 20
A20: Jersey Patch (Social Media) | B20: Jersey Patch Social Media | C20: Social Media | D20: Twitter/X | E20: Men's | F20: Basketball | G20: 78922.125 | H20: 947.0655 | S20: 12
A21: Jersey Patch (Social Media) | B21: Jersey Patch Social Media | C21: Social Media | D21: Facebook | E21: Women's | F21: Basketball | G21: 50119 | H21: 501.1875 | S21: 20
A22: Jersey Patch (Social Media) | B22: Jersey Patch Social Media | C22: Social Media | D22: Instagram | E22: Women's | F22: Basketball | G22: 90956.25 | H22: 1819.125 | S22: 12
A23: Jersey Patch (Social Media) | B23: Jersey Patch Social Media | C23: Social Media | D23: Twitter/X | E23: Women's | F23: Basketball | G23: 59951.25 | H23: 719.415 | S23: 10
A24: LED Rotational Signage (4 Min per Game/4 Rotations) | B24: Incremental Asset Package | C24: Broadcast | D24: FS1 | E24: Men's | F24: Basketball | G24: =P24/Q24*I24*O24 -> 360000 | H24: =G24/1000*S24 -> 5400 | I24: 90000 | N24: 1 | O24: =N24*R24 -> 2 | P24: 60 | Q24: 30 | R24: 2 | S24: 15
A25: LED Rotational Signage (4 Min per Game/4 Rotations) | B25: Incremental Asset Package | C25: Streaming | D25: ESPN+ | E25: Men's | F25: Basketball | G25: =P25/Q25*I25*O25 -> 39000 | H25: =G25/1000*S25 -> 585 | I25: 1500 | N25: 1 | O25: =N25*R25 -> 13 | P25: 60 | Q25: 30 | R25: 13 | S25: 15
A26: LED Rotational Signage (4 Min per Game/4 Rotations) | B26: Incremental Asset Package | C26: Streaming | D26: Pac-12 Network | E26: Men's | F26: Basketball | G26: =P26/Q26*I26*O26 -> 100000 | H26: =G26/1000*S26 -> 1500 | I26: 50000 | N26: 1 | O26: =N26*R26 -> 1 | P26: 60 | Q26: 30 | R26: 1 | S26: 15
A27: LED Rotational Signage (4 Min per Game/4 Rotations) | B27: Incremental Asset Package | C27: Onsite | D27: Onsite | E27: Men's | F27: Basketball | G27: =J27*K27*L27*N27 -> 33700.8 | H27: =G27/1000*S27 -> 674.016 | J27: 6018 | K27: 0.7 | L27: 8 | N27: 1 | O27: =N27*R27 -> 13 | R27: 13 | S27: 20
A28: LED Rotational Signage (4 Min per Game/4 Rotations) | B28: Incremental Asset Package | C28: Streaming | D28: FloCollege | E28: Women's | F28: Basketball | G28: =P28/Q28*I28*O28 -> 28000 | H28: =G28/1000*S28 -> 420 | I28: 1000 | N28: 1 | O28: =N28*R28 -> 14 | P28: 60 | Q28: 30 | R28: 14 | S28: 15
A29: LED Rotational Signage (4 Min per Game/4 Rotations) | B29: Incremental Asset Package | C29: Onsite | D29: Onsite | E29: Women's | F29: Basketball | G29: =J29*K29*L29*N29 -> 21560 | H29: =G29/1000*S29 -> 431.2 | J29: 3850 | K29: 0.7 | L29: 8 | N29: 1 | O29: =N29*R29 -> 14 | R29: 14 | S29: 20
A30: LED Rotational Signage (4 Min per Game/4 Rotations) | B30: Incremental Asset Package | C30: Broadcast | D30: BTN | E30: Women's | F30: Basketball | G30: =P30/Q30*I30*O30 -> 30000 | H30: =G30/1000*S30 -> 450 | I30: 15000 | N30: 1 | O30: =N30*R30 -> 1 | P30: 60 | Q30: 30 | R30: 1 | S30: 15

Sheet Package Breakdown by Asset
B16: Value | C16: Imp | D16: CPM
A17: Jersey Patch | B17: 36481.61 | C17: 1768232 | D17: =B17/C17*1000 -> 20.631687
A18: 15% IP Premium | B18: 10982
A19: LED Rotational Signage (4 Min per Game/4 Rotations) | B19: 9460.216 | C19: 612260.8 | D19: =B19/C19*1000 -> 15.451285
A20: Jersey Patch (Social Media) | B20: 7568.4555 | C20: 501404.88 | D20: =B20/C20*1000 -> 15.094499
A21: Commercial Units (30 sec) | B21: 7035 | C21: 469000 | D21: =B21/C21*1000 -> 15
A22: Email Marketing Inclusion | B22: 6600 | C22: 1320000 | D22: =B22/C22*1000 -> 5
A23: Sponsored Social Media Series 1 Per Week During School Year | B23: 3649.6 | C23: 235200 | D23: =B23/C23*1000 -> 15.517007
A24: Sideline Banners (tv visible, all sports) | B24: 2059.34 | C24: 411868 | D24: =B24/C24*1000 -> 5
A25: Web Banner Advertising | B25: 360 | C25: 45000 | D25: =B25/C25*1000 -> 8
A26: Grand Total | B26: =SUM(B17:B25) -> 84196.221 | C26: =SUM(C17:C25) -> 5362965.7 | D26: =B26/C26*1000 -> 15.699564

Sheet Package Breakdown by Sport
B12: Value | C12: Imp | D12: CPM
A13: Athletic Dept (Web, Digital, Social) | B13: 10609.6 | C13: 1600200 | D13: =B13/C13*1000 -> 6.6301712
A14: Basketball | B14: 62604.621 | C14: 3762765.7 | D14: =B14/C14*1000 -> 16.637927
A15: 15% IP Premium | B15: 10982
A16: Grand Total | B16: =SUM(B6:B15) -> 84196.221 | C16: =SUM(C6:C15) -> 5362965.7 | D16: =B16/C16*1000 -> 15.699564

Sheet Package Breakdown by Asset Cate
B22: Value | C22: Imp | D22: CPM
A23: Incremental Assets Total | B23: 85853.13 | C23: 6337462 | D23: 12.473154
A24: Jersey Patch Regular Season Total | B24: 27331.045 | C24: 2180461.2 | D24: 14.836912
A25: Jersey Social Media Total | B25: 35232.511 | C25: 3523287.1 | D25: 16.461753
A26: 10% IP Premium | B26: 14841
A27: Grand Total | B27: =SUM(B23:B26) -> 163257.69 | C27: =SUM(C23:C26) -> 12041210 | D27: 15.571769

Sheet Package Breakdown by Channel
A17: Channel | B17: Value | C17: Imp | D17: CPM
A18: FS1 | B18: 29055 | C18: 1267500 | D18: =B18/C18*1000 -> 22.923077
A19: ESPN+ | B19: 17314.61 | C19: 1473432 | D19: =B19/C19*1000 -> 11.751211 | G19: =B14*0.15 -> 10982.133
A20: 15% IP Premium | B20: 10982
A21: Instagram | B21: 7015.725 | C21: 350786.25 | D21: =B21/C21*1000 -> 20
A22: Email | B22: 6600 | C22: 1320000 | D22: =B22/C22*1000 -> 5
A23: Pac-12 Network | B23: 5032.5 | C23: 309250 | D23: =B23/C23*1000 -> 16.273242
A24: Facebook | B24: 2137.45 | C24: 213745.25 | D24: =B24/C24*1000 -> 9.9999883
A25: Twitter/X | B25: 2064.8805 | C25: 172073.38 | D25: =B25/C25*1000 -> 12
A26: BTN | B26: 2059.5 | C26: 118050 | D26: =B26/C26*1000 -> 17.445997
A27: Onsite | B27: 1154.556 | C27: 65128.8 | D27: =B27/C27*1000 -> 17.727273
A28: FloCollege | B28: 420 | C28: 28000 | D28: =B28/C28*1000 -> 15
A29: Website | B29: 360 | C29: 45000 | D29: =B29/C29*1000 -> 8
A30: Grand Total | B30: =SUM(B18:B29) -> 84196.221 | C30: =SUM(C18:C29) -> 5362965.7 | D30: =AVERAGE(D18:D19,D21:D29) -> 14.192799

Sheet Social Value
A1: Gender | B1: Category | C1: Asset Name | D1: Account Type | E1: Channel | F1: Estimated Reach % of Followers | G1: Marketplace CPM | H1: Total Follower Count | I1: Total Posts | J1: Impressions per Post | K1: Value per Post | L1: Total Impressions | M1: Total Value
A2: Womens | B2: Basketball | C2: Final Score Post | D2: Team-Specific | E2: Facebook | F2: 0.675 | G2: 10 | H2: 1100 | I2: 30 | J2: =L2/I2 -> 816.75 | K2: =M2/I2 -> 8.1675 | L2: =H2*F2*I2*1.1 -> 24502.5 | M2: =(L2/1000)*G2 -> 245.025
A3: Womens | B3: Basketball | C3: Game Day Post | D3: Team-Specific | E3: Facebook | F3: 0.675 | G3: 10 | H3: 1100 | I3: 30 | J3: =L3/I3 -> 668.25 | K3: =M3/I3 -> 6.6825 | L3: =H3*F3*I3*0.9 -> 20047.5 | M3: =(L3/1000)*G3 -> 200.475
A4: Womens | B4: Basketball | C4: Top Plays | D4: Team-Specific | E4: Facebook | F4: =37.5%/2 -> 0.1875 | G4: 10 | H4: 1100 | I4: 30 | J4: =L4/I4 -> 185.625 | K4: =M4/I4 -> 1.85625 | L4: =H4*F4*I4*0.9 -> 5568.75 | M4: =(L4/1000)*G4 -> 55.6875
A5: Womens | B5: Basketball | C5: Final Score Post | D5: Team-Specific | E5: Instagram Feed | F5: 0.375 | G5: 20 | H5: 3300 | I5: 30 | J5: =L5/I5 -> 1361.25 | K5: =M5/I5 -> 27.225 | L5: =H5*F5*I5*1.1 -> 40837.5 | M5: =(L5/1000)*G5 -> 816.75
A6: Womens | B6: Basketball | C6: Game Day Post | D6: Team-Specific | E6: Instagram Feed | F6: 0.375 | G6: 20 | H6: 3300 | I6: 30 | J6: =L6/I6 -> 1113.75 | K6: =M6/I6 -> 22.275 | L6: =H6*F6*I6*0.9 -> 33412.5 | M6: =(L6/1000)*G6 -> 668.25
A7: Womens | B7: Basketball | C7: Top Plays | D7: Team-Specific | E7: Instagram Feed | F7: =37.5%/2 -> 0.1875 | G7: 20 | H7: 3300 | I7: 30 | J7: =L7/I7 -> 556.875 | K7: =M7/I7 -> 11.1375 | L7: =H7*F7*I7*0.9 -> 16706.25 | M7: =(L7/1000)*G7 -> 334.125
A8: Womens | B8: Basketball | C8: Final Score Post | D8: Team-Specific | E8: Twitter/X | F8: 0.0525 | G8: 12 | H8: 7300 | I8: 30 | J8: =L8/I8 -> 421.575 | K8: =M8/I8 -> 5.0589 | L8: =H8*F8*I8*1.1 -> 12647.25 | M8: =(L8/1000)*G8 -> 151.767
A9: Womens | B9: Basketball | C9: Game Day Post | D9: Team-Specific | E9: Twitter/X | F9: 0.0525 | G9: 12 | H9: 7300 | I9: 30 | J9: =L9/I9 -> 344.925 | K9: =M9/I9 -> 4.1391 | L9: =H9*F9*I9*0.9 -> 10347.75 | M9: =(L9/1000)*G9 -> 124.173
A10: Womens | B10: Basketball | C10: Top Plays | D10: Team-Specific | E10: Twitter/X | F10: =37.5%/2 -> 0.1875 | G10: 12 | H10: 7300 | I10: 30 | J10: =L10/I10 -> 1231.875 | K10: =M10/I10 -> 14.7825 | L10: =H10*F10*I10*0.9 -> 36956.25 | M10: =(L10/1000)*G10 -> 443.475
A11: Mens | B11: Basketball | C11: Final Score Post | D11: Team-Specific | E11: Facebook | F11: 0.675 | G11: 10 | H11: 1800 | I11: 31 | J11: =L11/I11 -> 1336.5 | K11: =M11/I11 -> 13.365 | L11: =H11*F11*I11*1.1 -> 41431.5 | M11: =(L11/1000)*G11 -> 414.315
A12: Mens | B12: Basketball | C12: Game Day Post | D12: Team-Specific | E12: Facebook | F12: 0.675 | G12: 10 | H12: 1800 | I12: 31 | J12: =L12/I12 -> 1093.5 | K12: =M12/I12 -> 10.935 | L12: =H12*F12*I12*0.9 -> 33898.5 | M12: =(L12/1000)*G12 -> 338.985
A13: Mens | B13: Basketball | C13: Top Plays | D13: Team-Specific | E13: Facebook | F13: =37.5%/2 -> 0.1875 | G13: 10 | H13: 1800 | I13: 31 | J13: =L13/I13 -> 303.75 | K13: =M13/I13 -> 3.0375 | L13: =H13*F13*I13*0.9 -> 9416.25 | M13: =(L13/1000)*G13 -> 94.1625
A14: Mens | B14: Basketball | C14: Final Score Post | D14: Team-Specific | E14: Instagram Feed | F14: 0.375 | G14: 20 | H14: 4800 | I14: 31 | J14: =L14/I14 -> 1980 | K14: =M14/I14 -> 39.6 | L14: =H14*F14*I14*1.1 -> 61380 | M14: =(L14/1000)*G14 -> 1227.6
A15: Mens | B15: Basketball | C15: Game Day Post | D15: Team-Specific | E15: Instagram Feed | F15: 0.375 | G15: 20 | H15: 4800 | I15: 31 | J15: =L15/I15 -> 1620 | K15: =M15/I15 -> 32.4 | L15: =H15*F15*I15*0.9 -> 50220 | M15: =(L15/1000)*G15 -> 1004.4
A16: Mens | B16: Basketball | C16: Top Plays | D16: Team-Specific | E16: Instagram Feed | F16: =37.5%/2 -> 0.1875 | G16: 20 | H16: 4800 | I16: 31 | J16: =L16/I16 -> 810 | K16: =M16/I16 -> 16.2 | L16: =H16*F16*I16*0.9 -> 25110 | M16: =(L16/1000)*G16 -> 502.2
A17: Mens | B17: Basketball | C17: Final Score Post | D17: Team-Specific | E17: Twitter/X | F17: 0.0525 | G17: 12 | H17: 9300 | I17: 31 | J17: =L17/I17 -> 537.075 | K17: =M17/I17 -> 6.4449 | L17: =H17*F17*I17*1.1 -> 16649.325 | M17: =(L17/1000)*G17 -> 199.7919
A18: Mens | B18: Basketball | C18: Game Day Post | D18: Team-Specific | E18: Twitter/X | F18: 0.0525 | G18: 12 | H18: 9300 | I18: 31 | J18: =L18/I18 -> 439.425 | K18: =M18/I18 -> 5.2731 | L18: =H18*F18*I18*0.9 -> 13622.175 | M18: =(L18/1000)*G18 -> 163.4661
A19: Mens | B19: Basketball | C19: Top Plays | D19: Team-Specific | E19: Twitter/X | F19: =37.5%/2 -> 0.1875 | G19: 12 | H19: 9300 | I19: 31 | J19: =L19/I19 -> 1569.375 | K19: =M19/I19 -> 18.8325 | L19: =H19*F19*I19*0.9 -> 48650.625 | M19: =(L19/1000)*G19 -> 583.8075
M25: Sport | N25: Twitter | O25: Instagram | P25: Facebook
M26: Women's Basketball | N26: 7290 | O26: 3348 | P26: 1078
M27: Men's Basketball | N27: 9274 | O27: 4822 | P27: 1835

Sheet Pivot Table 3
E10: 23655

Sheet Game Pivot

Sheet Social Pivot

Sheet Full Breakdown
A1: Gender | B1: Sport | C1: Social Value | D1: Social Impressions | E1: Game Value | F1: Game Impressions | G1: Total Value | H1: Total Impressions
A2: Mens | B2: Basketball | C2: 4528.728 | D2: 300378.38 | E2: 31788.77 | F2: 1455917 | G2: =SUM(E2,C2) -> 36317.498 | H2: =SUM(F2,D2) -> 1756295.4
A3: Womens | B3: Basketball | C3: 3039.7275 | D3: 201026.25 | E3: 4693.11 | F3: 312315 | G3: =SUM(E3,C3) -> 7732.8375 | H3: =SUM(F3,D3) -> 513341.25
A4: Totals | C4: =SUM(C2:C3) -> 7568.4555 | D4: =SUM(D2:D3) -> 501404.62 | E4: =SUM(E2:E3) -> 36481.88 | F4: =SUM(F2:F3) -> 1768232 | G4: =SUM(E4,C4) -> 44050.336 | H4: =SUM(F4,D4) -> 2269636.6
I6: =G4*1.1 -> 48455.369

Sheet KEY
A1: Sport | B1: Game Length (sec) | C1: Onsite Exposure | D1: Imp/ Spec | E1: Streaming % of Broadcast | F1: Streaming Visibility (sec) | G1: Streaming Notes | I1: Onsite Notes
A2: Basketball | B2: =120*60 -> 7200 | C2: 0.65 | D2: 10 | E2: 0.06 | F2: =B2*E2 -> 432 | G2: constant torso framing on dribbles/free throws/coaching shots; high close-up density. | I2: Smaller venue + close proximity, lots of dead-ball, huddles, free throws.
A3: Football | B3: =202*60 -> 12120 | C3: 0.55 | D3: 8 | E3: 0.035 | F3: =B3*E3 -> 424.2 | G3: huge audiences, but lots of wide shots / helmets / pads / sideline cuts; patch readability is lower despite runtime. | I3: Distance is the limiter; patch “seen” often, but “readable” less. Videoboards help.
A4: Gymnastics | B4: =120*60 -> 7200 | C4: 0.85 | D4: 12 | E4: 0.075 | F4: =B4*E4 -> 540 | G4: lots of close-ups + slow-motion; if patch is on competition leotard (not warmups), visibility is strong. | I4: Close viewing, routines focus on athletes, slower pacing, lots of pauses.
A5: Baseball | B5: =180*60 -> 10800 | C5: 0.6 | D5: 7 | E5: 0.07 | F5: =B5*E5 -> 756 | G5: a lot of pitcher-batter wide framing + replay angles; patch shows in dugout/celebrations more than live pitch. | I5: Many fans watch from distance; best exposure during dugout moments, celebrations, close plays.
A6: Softball | B6: =120*60 -> 7200 | C6: 0.65 | D6: 8 | E6: 0.065 | F6: =B6*E6 -> 468 | G6: a lot of pitcher-batter wide framing + replay angles; patch shows in dugout/celebrations more than live pitch. | I6: Typically closer sightlines than baseball; more readable on close plays + dugout.
A7: Volleyball | B7: =120*60 -> 7200 | C7: 0.72 | D7: 9 | E7: 0.05 | F7: =B7*E7 -> 360 | G7: plenty of mid-shots and huddles, but also wide rally cam; moderate readability. | I7: Decent proximity, frequent huddles/celebrations; rally cam is wide but venue is small.
A8: Soccer | B8: =150*60 -> 9000 | C8: 0.5 | D8: 6 | E8: 0.02 | F8: =B8*E8 -> 180 | G8: sustained wide-angle field camera; few torso close-ups. | I8: Wide field viewing dominates; fewer close-range moments; patch readability is the limiter.
A9: Lacrosse | B9: =150*60 -> 9000 | C9: 0.5 | D9: 5 | E9: 0.02 | F9: =B9*E9 -> 180
A12: Network | B12: U.S TV Households/Total U.S Subscribers | C12: Distribution | D12: Visibility Weighting Factor | E12: Visibility Notes | G12: CPM | H12: CPM Notes | J12: Estimated Viewer Average
A13: ACCN | B13: 52000000 | C13: National Linear | D13: 0.5 | E13: Full HD broadcast, shoulder programming limited; patch clarity moderate | G13: 16 | H13: Conference network CPM below ESPN tier but above digital-only streams
A14: Astros.com | B14: 3000000 | C14: Streaming | D14: 0.35 | E14: Digital stream; variable production quality and camera tightness | G14: 12 | H14: Team-owned stream; lower demand advertiser base
A15: CBS (regular season) | B15: 88000000 | C15: National Linear | D15: 0.5 | E15: Premium national exposure; high production quality and camera clarity | G15: 35 | H15: Big 4 network sports CPM benchmark
A16: CBS (post season) | B16: 88000000 | C16: National Linear | D16: 0.5 | E16: Increased camera focus, higher stakes, more replay visibility | G16: 40 | H16: Premium live event demand; scarcity-driven pricing
A17: CBSSN | B17: 47000000 | C17: National Linear | D17: 0.35 | E17: National but secondary channel; moderate production visibility | G17: 20 | H17: Lower distribution vs CBS; mid-tier cable CPM
A18: ESPN | B18: 74000000 | C18: National Linear | D18: 0.5 | E18: Industry benchmark for sports broadcast clarity | G18: 32 | H18: Premium cable sports CPM anchor
A19: ESPN+ | B19: 25000000 | C19: Streaming | D19: 0.4 | E19: HD streaming; tighter cameras but lower scale vs linear | G19: 18 | H19: Streaming sports CPM discount vs linear
A20: ESPN2 | B20: 70000000 | C20: National Linear | D20: 0.45 | E20: Strong national distribution but secondary tier | G20: 24 | H20: Below ESPN flagship CPM
A21: ESPNU | B21: 36000000 | C21: National Linear | D21: 0.4 | E21: Collegiate-focused, lower audience concentration | G21: 20 | H21: Niche cable sports CPM
A22: FloCollege | B22: 1500000 | C22: Streaming | D22: 0.35 | E22: Subscription niche; variable production consistency | G22: 15 | H22: Specialty sports streaming CPM
A23: FOX (regular season) | B23: 88000000 | C23: National Linear | D23: 0.5 | E23: Big 4 broadcast quality and exposure | G23: 36 | H23: Comparable to CBS regular season
A24: FOX (post season) | B24: 88000000 | C24: National Linear | D24: 0.5 | E24: Enhanced viewership and replay density | G24: 40 | H24: Premium postseason CPM
... A32: TruTV | B32: 72000000 | C32: National Linear | D32: 0.5 | E32: NCAA spillover; lower advertiser demand | G32: 18 | H32: Discounted cable CPM
A33: CBSSN | C33: National Linear | D33: 0.42 | G33: 20
A34: SNY | C34: Regional Sports Network (RSN) | D34: 0.4 | G34: 16
A35: Big10+ | C35: Streaming | D35: 0.4 | E35: HD streaming; tighter cameras but lower scale vs linear | G35: 18 | H35: Streaming sports CPM discount vs linear
A36: America East TV | C36: Streaming | D36: 0.35 | E36: Basic conference digital production | G36: 8 | H36: Lower advertiser demand and reach
A37: LacrosseTV | C37: Streaming | D37: 0.35 | G37: 12
A38: Jasper Sports Network | C38: Streaming | D38: 0.35 | E38: Basic conference digital production | G38: 8 | H38: Lower advertiser demand and reach
A39: ACCN+ | C39: Streaming | D39: 0.4 | E39: HD streaming; tighter cameras but lower scale vs linear | G39: 18 | H39: Streaming sports CPM discount vs linear
A40: FS2 | C40: National Linear | D40: 0.5 | E40: Strong production quality; national cable reach | G40: 28 | H40: Slightly below ESPN CPM
A41: NBC Sports Philly | C41: Regional Sports Network (RSN) | D41: 0.4 | G41: 16
A42: MSG | C42: Regional Sports Network (RSN) | D42: 0.4 | G42: 16
A43: SEC Network | C43: National Linear | D43: 0.5 | E43: Full HD broadcast, shoulder programming limited; patch clarity moderate | G43: 16 | H43: Conference network CPM below ESPN tier but above digital-only streams
A44: SEC+ | C44: Streaming | D44: 0.4 | E44: HD streaming; tighter cameras but lower scale vs linear | G44: 18 | H44: Streaming sports CPM discount vs linear
A45: Youtube | D45: 0.35 | E45: Digital stream; variable production quality and camera tightness | G45: 12
A46: WWAX(The Wax) | C46: Regional Sports Network (RSN) | D46: 0.4 | G46: 16
A47: Monumental Sports Network | C47: Regional Sports Network (RSN) | D47: 0.4 | G47: 16
A48: YES Network | B48: 9000000 | C48: Regional Sports Network (RSN) | D48: 0.4 | G48: 16
A49: NESN | B49: 4000000 | C49: Regional Sports Network (RSN) | D49: 0.4 | G49: 16
...
